Workbook

Sheet Videos
A1: # | B1: Title | C1: Category | D1: Views | E1: Views (numeric) | F1: Age | G1: Duration
A2: 1 | B2: The MASSIVE Orlando projects and who's behind them | C2: New Construction/Development | D2: 19K | E2: 19000 | F2: 12 days ago | G2: 7:56
A3: 2 | B3: These 8 areas are driving Orlando's growth | C3: Neighborhood | D3: 10K | E3: 10000 | F3: 2 weeks ago | G3: 7:34
A4: 3 | B4: INSIDE a $9,500,000 Orlando Home. It's Actually Insane | C4: Luxury Home Tour | D4: 12K | E4: 12000 | F4: 1 month ago | G4: 13:37
A5: 4 | B5: Orlando Custom Home BOOM is happening in THIS Suburb! | C5: New Construction/Development | D5: 6.8K | E5: 6800 | F5: 1 month ago | G5: 13:52
A6: 5 | B6: Small Towns Near Orlando Everyone's Moving To Right Now | C6: Neighborhood | D6: 72K | E6: 72000 | F6: 1 month ago | G6: 11:24
A7: 6 | B7: Winter Garden vs Winter Park - Orlando's Best Places to Live? | C7: Comparison | D7: 17K | E7: 17000 | F7: 2 months ago | G7: 10:57
A8: 7 | B8: Moving to Orlando for Disney? Here's Where People Buy | C8: Relocation | D8: 52K | E8: 52000 | F8: 3 months ago | G8: 12:56
A9: 8 | B9: Celebration Florida is Changing (2026 Update) | C9: Neighborhood | D9: 27K | E9: 27000 | F9: 3 months ago | G9: 10:49
A10: 9 | B10: Orlando's Hottest Neighborhoods in 2026 | C10: Neighborhood | D10: 12K | E10: 12000 | F10: 3 months ago | G10: 16:45
A11: 10 | B11: Orlando's Hottest Suburb Just Added Five New Neighborhoods | C11: New Construction/Development | D11: 21K | E11: 21000 | F11: 4 months ago | G11: 25:01
A12: 11 | B12: MAJOR Projects Shaping Orlando in 2026 | C12: New Construction/Development | D12: 17K | E12: 17000 | F12: 5 months ago | G12: 10:38
A13: 12 | B13: Orlando's Hidden Neighborhoods Everyone Should Know | C13: Neighborhood | D13: 15K | E13: 15000 | F13: 5 months ago | G13: 16:24
... A271: 270 | B271: Living in Oakland Park [Winter Garden] | C271: Neighborhood | D271: 6.7K | E271: 6700 | F271: 5 years ago | G271: 3:40

Sheet Category Summary
A1: Category | B1: Video Count | C1: Total Views | D1: Avg Views | E1: % of Videos
A2: Comparison | B2: =COUNTIF(Videos!C:C,A2) -> 16 | C2: =SUMIF(Videos!C:C,A2,Videos!E:E) -> 301500 | D2: =IFERROR(C2/B2,0) -> 18843.75 | E2: =B2/270 -> 0.059259259
A3: Lifestyle/Local | B3: =COUNTIF(Videos!C:C,A3) -> 24 | C3: =SUMIF(Videos!C:C,A3,Videos!E:E) -> 675900 | D3: =IFERROR(C3/B3,0) -> 28162.5 | E3: =B3/270 -> 0.088888889
A4: Luxury Home Tour | B4: =COUNTIF(Videos!C:C,A4) -> 26 | C4: =SUMIF(Videos!C:C,A4,Videos!E:E) -> 3018500 | D4: =IFERROR(C4/B4,0) -> 116096.15 | E4: =B4/270 -> 0.096296296
A5: Market/News | B5: =COUNTIF(Videos!C:C,A5) -> 40 | C5: =SUMIF(Videos!C:C,A5,Videos!E:E) -> 516483 | D5: =IFERROR(C5/B5,0) -> 12912.075 | E5: =B5/270 -> 0.14814815
A6: Neighborhood | B6: =COUNTIF(Videos!C:C,A6) -> 75 | C6: =SUMIF(Videos!C:C,A6,Videos!E:E) -> 1930300 | D6: =IFERROR(C6/B6,0) -> 25737.333 | E6: =B6/270 -> 0.27777778
A7: New Construction/Development | B7: =COUNTIF(Videos!C:C,A7) -> 42 | C7: =SUMIF(Videos!C:C,A7,Videos!E:E) -> 842900 | D7: =IFERROR(C7/B7,0) -> 20069.048 | E7: =B7/270 -> 0.15555556
A8: Other | B8: =COUNTIF(Videos!C:C,A8) -> 17 | C8: =SUMIF(Videos!C:C,A8,Videos!E:E) -> 88500 | D8: =IFERROR(C8/B8,0) -> 5205.8824 | E8: =B8/270 -> 0.062962963
A9: Relocation | B9: =COUNTIF(Videos!C:C,A9) -> 24 | C9: =SUMIF(Videos!C:C,A9,Videos!E:E) -> 888300 | D9: =IFERROR(C9/B9,0) -> 37012.5 | E9: =B9/270 -> 0.088888889
A10: Theme Park | B10: =COUNTIF(Videos!C:C,A10) -> 6 | C10: =SUMIF(Videos!C:C,A10,Videos!E:E) -> 21800 | D10: =IFERROR(C10/B10,0) -> 3633.3333 | E10: =B10/270 -> 0.022222222
A11: TOTAL | B11: =SUM(B2:B10) -> 270 | C11: =SUM(C2:C10) -> 8284183 | D11: =IFERROR(C11/B11,0) -> 30682.159 | E11: =SUM(E2:E10) -> 1

Sheet Top 20 by Views
A1: Rank | B1: Title | C1: Category | D1: Views | E1: Age
A2: 1 | B2: Shaquille O'Neal's $16 Million Mansion Tour in Orlando Florida | C2: Luxury Home Tour | D2: 2000000 | E2: 5 years ago
A3: 2 | B3: The Villages Lifestyle Visit | C3: Lifestyle/Local | D3: 490000 | E3: 5 years ago
A4: 3 | B4: Inside Walt Disney's Newest Golden Oak Home | C4: Luxury Home Tour | D4: 198000 | E4: 2 years ago
A5: 4 | B5: The $4,550,000 Way to Live at Disney World - Golden Oak Home For Sale | C5: Luxury Home Tour | D5: 169000 | E5: 2 years ago
A6: 5 | B6: Disney's Golden Oak Neighborhood | C6: Luxury Home Tour | D6: 143000 | E6: 4 years ago
A7: 6 | B7: MASSIVE Orlando Construction Projects That Will Change How You Live | C7: New Construction/Development | D7: 111000 | E7: 1 year ago
A8: 7 | B8: Orlando Locals Spill the Truth About Living Here | C8: Relocation | D8: 110000 | E8: 1 year ago
A9: 8 | B9: Your Guide to Celebration Florida: The Town Disney Built | C9: Neighborhood | D9: 101000 | E9: 2 years ago
A10: 9 | B10: Inside a $15,850,000 Home at Walt Disney World's Golden Oak | C10: Luxury Home Tour | D10: 100000 | E10: 1 year ago
A11: 10 | B11: Moving to Florida - Things I Wish I Knew Before Moving Here | C11: Relocation | D11: 90000 | E11: 4 years ago
A12: 11 | B12: Moving to Orlando | 8 things youll want to know | C12: Relocation | D12: 83000 | E12: 3 years ago
A13: 12 | B13: Pros and Cons of living in a Gated Community | C13: Relocation | D13: 82000 | E13: 5 years ago
... A21: 20 | B21: Here's where Orlando is headed | C21: Market/News | D21: 59000 | E21: 1 year ago

Sheet Strategy Evolution
A1: Category | B1: Year 1 (most recent) | C1: Year 2 | D1: Year 3 | E1: Year 4 | F1: Year 5 | G1: Year 6 (oldest) | H1: Total
A2: Comparison | B2: 2 | C2: 2 | D2: 3 | E2: 5 | F2: 3 | G2: 1 | H2: =SUM(B2:G2) -> 16
A3: Lifestyle/Local | B3: 1 | C3: 0 | D3: 2 | E3: 3 | F3: 9 | G3: 9 | H3: =SUM(B3:G3) -> 24
A4: Luxury Home Tour | B4: 2 | C4: 6 | D4: 3 | E4: 4 | F4: 5 | G4: 6 | H4: =SUM(B4:G4) -> 26
A5: Market/News | B5: 3 | C5: 2 | D5: 5 | E5: 10 | F5: 15 | G5: 5 | H5: =SUM(B5:G5) -> 40
A6: Neighborhood | B6: 7 | C6: 10 | D6: 15 | E6: 12 | F6: 13 | G6: 18 | H6: =SUM(B6:G6) -> 75
A7: New Construction/Development | B7: 9 | C7: 8 | D7: 4 | E7: 7 | F7: 13 | G7: 1 | H7: =SUM(B7:G7) -> 42
A8: Other | B8: 0 | C8: 0 | D8: 3 | E8: 0 | F8: 3 | G8: 11 | H8: =SUM(B8:G8) -> 17
A9: Relocation | B9: 2 | C9: 2 | D9: 8 | E9: 3 | F9: 5 | G9: 4 | H9: =SUM(B9:G9) -> 24
A10: Theme Park | B10: 2 | C10: 0 | D10: 0 | E10: 1 | F10: 0 | G10: 3 | H10: =SUM(B10:G10) -> 6
A11: TOTAL | B11: =SUM(B2:B10) -> 28 | C11: =SUM(C2:C10) -> 30 | D11: =SUM(D2:D10) -> 43 | E11: =SUM(E2:E10) -> 45 | F11: =SUM(F2:F10) -> 66 | G11: =SUM(G2:G10) -> 58 | H11: =SUM(H2:H10) -> 270

Sheet Year 1 Playbook
A1: Ken's Year-1 Title (5 years ago) | B1: Category | C1: Views | D1: NH Equivalent Idea
A2: Shaquille O'Neal's $16 Million Mansion Tour in Orlando Florida | B2: Luxury Home Tour | C2: 2000000
A3: The Villages Lifestyle Visit | B3: Lifestyle/Local | C3: 490000 | D3: Retirement community deep-dive — pick a NH 55+
A4: Pros and Cons of living in a Gated Community | B4: Relocation | C4: 82000 | D4: Pros and Cons of buying in a private community
A5: Windermere Luxury Home Tour | B5: Luxury Home Tour | C5: 64000
A6: Lake Nona | An Inside Look | Orlando Florida | B6: Neighborhood | C6: 41000
A7: Living In Reunion Florida | B7: Neighborhood | C7: 39000
A8: 7 Best Orlando Suburbs | B8: Neighborhood | C8: 38000 | D8: 7 Best Manchester-Area Suburbs
A9: Moving to Clermont, Florida | B9: Neighborhood | C9: 30000 | D9: Moving to Milford, NH
A10: Disney Fans Live Here [Top 3 Neighborhoods] | B10: Neighborhood | C10: 28000 | D10: Boston Commuters Live Here [Top 3 NH Towns]
A11: Best Orlando Condo Buildings | B11: Neighborhood | C11: 26000 | D11: Best Manchester & Nashua Condo Buildings
A12: Moving to Dr. Phillips | Orlando, FL | Community Tour | B12: Neighborhood | C12: 26000 | D12: Moving to Bedford, NH | Community Tour
A13: Moving to Mount Dora, Florida | B13: Neighborhood | C13: 24000 | D13: Moving to Peterborough, NH
A14: Downtown Winter Garden Florida | Tour, Restaurants, and Shopping | B14: Neighborhood | C14: 22000
A15: Life in Celebration, Florida | B15: Neighborhood | C15: 20000 | D15: Life in Mont Vernon, NH
A16: How Do Homeowners Associations Work? | B16: Other | C16: 18000 | D16: How Do NH Property Taxes Actually Work?
A17: High Paying Jobs In Orlando | B17: Market/News | C17: 17000
A18: Living in Winter Park vs Windermere | B18: Comparison | C18: 17000 | D18: Living in Amherst vs Hollis
A19: Best Places to Live in Celebration, Florida | B19: Neighborhood | C19: 16000 | D19: Best Places to Live in Amherst, NH
A20: Lakefront Living in Windermere, Florida [New Listing Alert!] | B20: Luxury Home Tour | C20: 16000 | D20: Lakefront living: Lake Winnipesaukee & Squam
A21: Orlando's Hidden Gem Neighborhoods | B21: Neighborhood | C21: 15000 | D21: NH's Hidden Gem Towns
A22: Horizon West, Florida (Winter Garden) | B22: Neighborhood | C22: 12000 | D22: The Souhegan Valley: NH's hidden growth corridor
A23: Moving to Orlando : 5 Year Update | Orlando, Florida | B23: Relocation | C23: 12000
A24: Orlando's Coming Housing Crash | B24: Market/News | C24: 12000
A25: Living in Baldwin Park [Orlando, Florida] | B25: Neighborhood | C25: 11000 | D25: Living in Amherst, NH
A26: Winter Garden, Florida - On the Street! | B26: Lifestyle/Local | C26: 10000
A27: Keene's Pointe Neighborhood [Windermere, Florida] | B27: Neighborhood | C27: 10000
A28: Moving to Downtown Orlando | B28: Neighborhood | C28: 10000 | D28: Moving to Downtown Nashua
A29: Most expensive home sales in Orlando 2020 | B29: Luxury Home Tour | C29: 9800
A30: Coming To Orlando 2021 | B30: New Construction/Development | C30: 9700
A31: Life in Orlando | B31: Lifestyle/Local | C31: 9600 | D31: Life in Southern NH
A32: The BEST pizza in Orlando? | B32: Lifestyle/Local | C32: 8200 | D32: The BEST pizza in southern NH
A33: The BEST Donut in Orlando | B33: Lifestyle/Local | C33: 8200 | D33: The BEST bakery in the Souhegan Valley
A34: Guide to Orlando - Ken Pozek | B34: Relocation | C34: 7000
A35: Living in Oakland Park [Winter Garden] | B35: Neighborhood | C35: 6700 | D35: Living in New Boston, NH
A36: Orlando Florida - Man on the Street Interviews | B36: Lifestyle/Local | C36: 6400
A37: 5 Reasons Why People Are Moving to Orlando | B37: Relocation | C37: 5700 | D37: 5 Reasons Floridians Are Moving to NH
A38: Orlando Lake Living - Boat and house tour | B38: Lifestyle/Local | C38: 5000
A39: Navigating Orlando's Housing Market | B39: Market/News | C39: 4800
A40: What $1 Million Buys: Winter Garden Home Tour | B40: Luxury Home Tour | C40: 4700
...
